Workbook

Sheet Fase 1-3
C1: H B O - I C T B E O O R D E L I N G S F O R M U L I E R A F S T U D E R E N
C2: Student: | D2: William van der Meijden | E2: Bedrijfsmentor: | F2: Reinier van Reenen | G2: Datum fasegesprek 1:
C3: Studentnummer: | D3: 19137400 | E3: Afstudeerbedrijf: | F3: Sogeti | G3: Datum fasegesprek 2:
C4: Eerste beoordelaar: | D4: Klaas Jan Mollema | E4: Differentiatie: | F4: ID | G4: Datum fasegesprek 3:
C5: Tweede beoordelaar: | D5: Jelle Hijlarides | E5: Afstudeerprogramma: | F5: ID
E8: Keuring | F8: Fase 1 | G8: Fase 2 | H8: fase 3
C9: Beroepstaak | D9: Beschrijving beroepstaak | E9: Opeleverde producten: Afstudeerplan | F9: Opgeleverde producten: plan van aanpak Requirements.docx Onderzoeksrapport.docx Reflectielogboek.docx Chart Projectplanning.xlsx Interview Johan Interview Marijn Interview Reinier | G9: Opgeleverde producten: - - | H9: Opgeleverde producten: - - | I9: Eindbeoordeling
B10: Verplichte beroepstaken | C10: A-1 Analyseren probleemdomein & opstellen probleemstelling | D10: =VLOOKUP(C10,Admin!$C:$D,2,FALSE) -> De student brengt helder in kaart waar, wanneer, voor wie en waarom welke problemen zich voordoen, wat de uitgangssituatie is, welke risico's er mogelijk zijn en welke (f)actoren daarbij een rol spelen. | E10: Voldoende | F10: Voldoende | G10: -- Keuze -- | H10: -- Keuze -- | I10: -- keuze --
E11: duidelijke opdrachtomschrijving | F11: desk research; demi gestructureerde interviews; stakeholder analyse; risico analyse. In de interviews technische, maar ookm gebruikersgerichtte vragen gesteld. Daaarnaast ook de business onderzocht. Stakeholder analyse gedaan. | G11: Toelichting beoordeling en afspraken (feedback en feed forward): | H11: Toelichting beoordeling en afspraken (feedback en feed forward):
C12: G-a Effectief (Internationaal) Communiceren | D12: =VLOOKUP(C12,Admin!$C:$D,2,FALSE) -> De student communiceert, schriftelijk en mondeling, op zelfbewuste, strategische en adequate wijze aan een doelgroep gerelateerde boodschappen richting individuen en kleine en grote groepen | E12: Voldoende | F12: Voldoende | G12: -- Keuze -- | H12: -- Keuze -- | I12: -- keuze --
E13: duidelijk plan | F13: William communiceert zowel op schrift als in de presentatie erg helder. Het wordt snel duidelijk wat hij van plan is; hoe het project in elkaar steekt en wat er voor probleem opgelost moet worden Documenten in begrijpelijke taal geschreven (hier ook op gelet). Visuele hulpmiddelen gebruikt.. | G13: Toelichting beoordeling en afspraken (feedback en feed forward): | H13: Toelichting beoordeling en afspraken (feedback en feed forward):
C14: G-c Kritisch, onderzoekend & methodisch werken | D14: =VLOOKUP(C14,Admin!$C:$D,2,FALSE) -> De student hanteert hoge kwaliteitsnormen voor anderen en zichzelf en stelt zichzelf vragen. Op zoek naar antwoorden hanteert de student gestandaardiseerde methoden/technieken/processen, en relevante en adequate argumentatie. | E14: Onvoldoende | F14: Voldoende | G14: -- Keuze -- | H14: -- Keuze -- | I14: -- keuze --
E15: onderbouwing vanuit literatuur is niet aanwezig, maar die volgt vast bij het plan van aanpak | F15: Onderbouwing vanuit literatuur is aanwezig. Methodisch gewerkt en ook in de planvorming uitgegaan van methodische aanpak. Kwalitatief onderzoek; interview analyse; SWOT analyse; Moscow; Waterval bewust gekozen voor deze fase; Scrum voor de volgende fase. Slime tabel gebruikt voor vergeleiking van oplossingen. | G15: Toelichting beoordeling en afspraken (feedback en feed forward): | H15: Toelichting beoordeling en afspraken (feedback en feed forward):
C16: G-f Leren leren: voorbereiden op volgende studiefase & beroep | D16: =VLOOKUP(C16,Admin!$C:$D,2,FALSE) -> De student is in staat het eigen leerproces vorm te geven waarbij voorbereid wordt op life-long-learning. | E16: Voldoende | F16: Voldoende | G16: -- Keuze -- | H16: -- Keuze -- | I16: -- keuze --
E17: duidelijk plan | F17: Begin gemaakt met reflectie. Duidelijk hoe ontvangen feedback direct verwerkt wordt. Reflectie mag naast de feedback van docenten en begeleider ook gaan bestaan uit reflectie op eigen functioneren. | G17: Toelichting beoordeling en afspraken (feedback en feed forward): | H17: Toelichting beoordeling en afspraken (feedback en feed forward):
C18: C-1 Ontwerpen software | D18: =VLOOKUP(C18,Admin!$C:$D,2,FALSE) -> De student maakt op basis van analyses en best practices gemotiveerde keuzes voor de opbouw van een software project. Zowel op micro (binnen modules), meso (tussen modules) als macro (module selectie) niveau. | E18: Voldoende | F18: Nog niet voldoende | G18: -- Keuze -- | H18: -- Keuze -- | I18: -- keuze --
E19: activiteiten en planning lijken passend bij de opdracht. | F19: start gemaakt met het verzamelen van requirements. Rest volgt in de volgende fase. | G19: Toelichting beoordeling en afspraken (feedback en feed forward): | H19: Toelichting beoordeling en afspraken (feedback en feed forward):
C20: D-1 Realiseren van software | D20: =VLOOKUP(C20,Admin!$C:$D,2,FALSE) -> De student ontwikkelt een onderbouwd softwareproduct op basis van een ontwerp. Hierbij wordt gebruik gemaakt van programmeer-, opmaak- en scripttalen. Er kan gebruik gemaakt worden van bestaande libraries en frameworks of begonnen worden 'from scratch'. | E20: Voldoende | F20: Niet van toepassing (in deze fase) | G20: -- Keuze -- | H20: -- Keuze -- | I20: -- keuze --
E21: activiteiten en planning lijken passend bij de opdracht. | F21: Toelichting beoordeling en afspraken (feedback en feed forward): | G21: Toelichting beoordeling en afspraken (feedback en feed forward): | H21: Toelichting beoordeling en afspraken (feedback en feed forward):
C22: D-2 Testen & Evalueren | D22: =VLOOKUP(C22,Admin!$C:$D,2,FALSE) -> De student toetst of een ontwikkeld ICT product of beleid voldoet aan de opgestelde (niet-)functionele requirements. Hierbij wordt planmatig en volgens best practices gewerkt en waar mogelijk wordt het proces geautomatiseerd. Er wordt aandacht besteed aan het formaliseren van testcases en evaluatiecriteria | E22: Voldoende | F22: Niet van toepassing (in deze fase) | G22: -- Keuze -- | H22: -- Keuze -- | I22: -- keuze --
E23: activiteiten en planning lijken passend bij de opdracht. | F23: Toelichting beoordeling en afspraken (feedback en feed forward): | G23: Toelichting beoordeling en afspraken (feedback en feed forward): | H23: Toelichting beoordeling en afspraken (feedback en feed forward):
C24: -- Selecteer beroepstaak -- | D24: =VLOOKUP(C24,Admin!$C:$D,2,FALSE) | E24: -- Keuze -- | F24: -- Keuze -- | G24: -- Keuze -- | H24: -- Keuze -- | I24: -- keuze --
E25: Toelichting beoordeling en afspraken (feedback en feed forward): | F25: Toelichting beoordeling en afspraken (feedback en feed forward): | G25: Toelichting beoordeling en afspraken (feedback en feed forward): | H25: Toelichting beoordeling en afspraken (feedback en feed forward):
D26: Extra ruimte voor overige opmerkingen / onderwerpen die besproken zijn tijdens het fasegesprek: | F26: Beoordelingen zijn voor deze fase: je bent dus voor deze fase op niveau bezig voor je algemene beroepstaken. | H26: Beoordeling en ondertekening:
H27: Indicatief cijfer: | I27: =Resultaat!B16
H28: Eindcijfer:
H29: Eerste beoordelaar:
H30: Tweede beoordelaar:
H31: Naam gecommitteerde:
H32: Toelichting op beoordeling:
H33: Toelichting op beoordeling:
H34: Indien onvoldoende (graag het beoordelingsformulier na het herstelgesprek nogmaals inleveren met hierin de afspraken):
H35: Datum herstelgesprek:
H36: Gemaakte afspraken tijdens het herstelgesprek:
H37: Inleverdatum fase 4:

Sheet Herkansing
C1: ='Fase 1-3'!C1 -> H B O - I C T B E O O R D E L I N G S F O R M U L I E R A F S T U D E R E N | I1: -- Keuze -- | L1: bt1 | M1: =IF(E9=$I$1,"",IF(E9=$I$2,$J$2,IF(E9=$I$3,$J$3,IF(E9=$I$4,$J$4,IF(E9=$I$5,$J$5,IF(E9=$I$6,$J$6,)))))) -> 0 | O1: 5 | P1: 6,5 - 7
C2: Student: | D2: ='Fase 1-3'!D2 -> William van der Meijden | E2: Bedrijfsmentor: | F2: ='Fase 1-3'!F2 -> Reinier van Reenen | I2: Goed | J2: 5 | L2: bt2 | M2: =IF(E11=$I$1,"",IF(E11=$I$2,$J$2,IF(E11=$I$3,$J$3,IF(E11=$I$4,$J$4,IF(E11=$I$5,$J$5,IF(E11=$I$6,$J$6,)))))) -> 0 | O2: 4.5 | P2: 6 - 7
C3: Studentnummer: | D3: ='Fase 1-3'!D3 -> 19137400 | E3: Afstudeerbedrijf: | F3: ='Fase 1-3'!F3 -> Sogeti | I3: Voldoende | J3: 4 | L3: bt3 | M3: =IF(E13=$I$1,"",IF(E13=$I$2,$J$2,IF(E13=$I$3,$J$3,IF(E13=$I$4,$J$4,IF(E13=$I$5,$J$5,IF(E13=$I$6,$J$6,)))))) -> 0 | O3: 4 | P3: 6 - 6,5
C4: Eerste beoordelaar: | D4: ='Fase 1-3'!D4 -> Klaas Jan Mollema | E4: Differentiatie: | F4: ='Fase 1-3'!F4 -> ID | I4: Twijfel | J4: 3 | L4: bt4 | M4: =IF(E15=$I$1,"",IF(E15=$I$2,$J$2,IF(E15=$I$3,$J$3,IF(E15=$I$4,$J$4,IF(E15=$I$5,$J$5,IF(E15=$I$6,$J$6,)))))) -> 0 | O4: 3.5 | P4: 5,5 - 7
C5: Tweede beoordelaar: | D5: ='Fase 1-3'!D5 -> Jelle Hijlarides | E5: Afstudeerprogramma: | F5: ='Fase 1-3'!F5 -> ID | I5: Onvoldoende | J5: 2 | L5: bt5 | M5: =IF(E17=$I$1,"",IF(E17=$I$2,$J$2,IF(E17=$I$3,$J$3,IF(E17=$I$4,$J$4,IF(E17=$I$5,$J$5,IF(E17=$I$6,$J$6,)))))) -> 0 | O5: 3 | P5: 5 - 6
I6: Niet / nauwelijks gedemonstreerd | J6: 1 | L6: bt6 | M6: =IF(E19=$I$1,"",IF(E19=$I$2,$J$2,IF(E19=$I$3,$J$3,IF(E19=$I$4,$J$4,IF(E19=$I$5,$J$5,IF(E19=$I$6,$J$6,)))))) -> 0 | O6: 2.5 | P6: 4 - 5,5
E7: Herkansing/ eindassessment (Fase 4) | L7: bt7 | M7: =IF(E21=$I$1,"",IF(E21=$I$2,$J$2,IF(E21=$I$3,$J$3,IF(E21=$I$4,$J$4,IF(E21=$I$5,$J$5,IF(E21=$I$6,$J$6,)))))) -> 0 | O7: 2 | P7: 3 - 5
C8: Beroepstaak | D8: Beschrijving beroepstaak | E8: Opgeleverde producten: - - | L8: bt8 | M8: =IF(E23=$I$1,"",IF(E23=$I$2,$J$2,IF(E23=$I$3,$J$3,IF(E23=$I$4,$J$4,IF(E23=$I$5,$J$5,IF(E23=$I$6,$J$6,)))))) -> 0 | O8: 1.5 | P8: 2 - 4
B9: Verplichte beroepstaken | C9: A-1 Analyseren probleemdomein & opstellen probleemstelling | D9: =VLOOKUP(C9,Admin!$C:$D,2,FALSE) -> De student brengt helder in kaart waar, wanneer, voor wie en waarom welke problemen zich voordoen, wat de uitgangssituatie is, welke risico's er mogelijk zijn en welke (f)actoren daarbij een rol spelen. | E9: -- keuze -- | L9: gem rang | M9: =MROUND(AVERAGE(M1:M8),0.5) -> 0 | O9: 1 | P9: 1 - 3
E10: Onderbouwing beoordeling: | L10: indicatief | M10: =IF(VLOOKUP($M$9,$O$1:$P$9,2,FALSE)=0,0,VLOOKUP($M$9,$O$1:$P$9,2,FALSE)) -> #N/A
C11: G-a Effectief (Internationaal) Communiceren | D11: =VLOOKUP(C11,Admin!$C:$D,2,FALSE) -> De student communiceert, schriftelijk en mondeling, op zelfbewuste, strategische en adequate wijze aan een doelgroep gerelateerde boodschappen richting individuen en kleine en grote groepen | E11: -- keuze --
E12: Onderbouwing beoordeling:
C13: G-c Kritisch, onderzoekend & methodisch werken | D13: =VLOOKUP(C13,Admin!$C:$D,2,FALSE) -> De student hanteert hoge kwaliteitsnormen voor anderen en zichzelf en stelt zichzelf vragen. Op zoek naar antwoorden hanteert de student gestandaardiseerde methoden/technieken/processen, en relevante en adequate argumentatie. | E13: -- keuze --
E14: Onderbouwing beoordeling:
C15: G-f Leren leren: voorbereiden op volgende studiefase & beroep | D15: =VLOOKUP(C15,Admin!$C:$D,2,FALSE) -> De student is in staat het eigen leerproces vorm te geven waarbij voorbereid wordt op life-long-learning. | E15: -- keuze --
E16: Onderbouwing beoordeling:
C17: -- Selecteer beroepstaak -- | D17: =VLOOKUP(C17,Admin!$C:$D,2,FALSE) | E17: -- keuze --
E18: Onderbouwing beoordeling:
C19: -- Selecteer beroepstaak -- | D19: =VLOOKUP(C19,Admin!$C:$D,2,FALSE) | E19: -- keuze --
E20: Onderbouwing beoordeling:
C21: -- Selecteer beroepstaak -- | D21: =VLOOKUP(C21,Admin!$C:$D,2,FALSE) | E21: -- keuze --
E22: Onderbouwing beoordeling:
C23: -- Selecteer beroepstaak -- | D23: =VLOOKUP(C23,Admin!$C:$D,2,FALSE) | E23: -- keuze --
E24: Onderbouwing beoordeling:
E26: Beoordeling en ondertekening:
E27: indicatief cijfer: | F27: =her!B16
E28: Eindcijfer:
E29: Eerste beoordelaar:
E30: Tweede beoordelaar:
E31: Naam gecommitteerde:
E32: Datum:
E33: Proces verbaal

Sheet Docentvragen per fase
A1: Hieronder staan voorbeeldvragen die een examinator zou kunnen stellen tijdens het fasegesprek | C1: Het moment waarop de vraag met name relevant is
C2: fase 1 | D2: fase 2 | E2: fase 3
A3: Algemeen | B3: Waarom is dat wat je nu oplevert van goede kwaliteit? | C3: x | D3: x
B4: Is je opdracht nog dezelfde als die in het voortraject is goedgekeurd? | C4: x | D4: x | E4: x
B5: Heb je voldoende uitdaging? | C5: x | D5: x
B6: Ben je in staat de beroepstaken te demonstreren met het uitvoeren van de opdracht? | C6: x | D6: x
B7: Hoe ziet volgens jou de beoordeling van je afstuderen eruit? | C7: x | D7: x
B8: Waar ben je het meest trots op? | C8: x | D8: x | E8: x
B9: Welke beroepsproducten ga je in de volgende fases opleveren? | C9: x | D9: x | E9: x
B10: Welke beroepstaken demonstreer je bij de volgende fases? | C10: x | D10: x | E10: x
B11: Heb je het naar je zin, wat maakt het project interessant? | C11: x | D11: x | E11: x
B12: Welke professionele vaardigheid van bedrijfsmentor/opdrachtgever/medewerkers zou je graag ook willen beheersen? | C12: x | D12: x | E12: x
B13: Heb je het idee dat je voor school iets anders moet doen dan voor het bedrijf? | C13: x | D13: x | E13: x
B14: Hoe zorg je ervoor dat alle betrokkenen bij jouw afstuderen doen wat er van ze verwacht wordt? | C14: x | D14: x | E14: x
B15: Zijn er punten niet aan bod gekomen, die je nog wel onder de aandacht wilt brengen? | E15: x
A17: Aanpak | B17: Hoe heb je de feedback op je afstudeerplan verwerkt in je plan van aanpak? | C17: x
B18: Welke inzichten met betrekking tot de aanleiding, probleemstelling en doelstelling heeft de afgelopen fase opgeleverd? | C18: x
B19: Hebben nieuwe inzichten geleid tot een andere aanpak/planning? | C19: x | D19: x | E19: x
B20: Hebben deze inzichten geleid tot een andere selectie van te demonstreren beroepstaken? | C20: x | D20: x | E20: x
B21: Hoe is bepaald welke stakeholders betrokken dienen te worden bij het project? Heeft dat geleid tot aanpassingen van je aanpak/planning? | C21: x
B22: Kan je uitleggen wanneer de kwaliteit van het opgeleverde product goed is? | C22: x | D22: x | E22: x
B23: Hoe is bepaald waaraan de op te leveren producten moeten voldoen om de kwaliteit ervan te waarborgen? | C23: x
B24: Welke criteria worden gebruikt om de kwaliteit van je producten te vaststellen? | C24: x | D24: x | E24: x
B25: Welke stakeholders heb je nodig om de kwaliteit van je beroepsproducten aan te tonen? | C25: x | D25: x
B26: Welke ruimte ervaar je om zelf keuzes t.a.v. je aanpak en uitvoering van je opdracht te maken? | C26: x | D26: x | E26: x
A28: Kwaliteit beroepsproduct | B28: Op welke wijze gaat het beroepsproduct bijdragen aan de totstandkoming van het eindproduct? | C28: x | D28: x | E28: x
B29: Hoe hebben eerder opgeleverde beroepsproducten bijgedragen aan de totstandkoming van dit beroepsproduct? | D29: x | E29: x
B30: Hoe heb je de validiteit van je bevindingen vastgesteld/vastgelegd? | D30: x | E30: x
B31: Hoe heb je de betrouwbaarheid van je bevindingen vastgesteld/vastgelegd? | D31: x | E31: x
B32: Hoe heb je de traceerbaarheid van je bevindingen vastgesteld/vastgelegd? | D32: x | E32: x
B33: Hoe heb je de volledigheid van je bevindingen vastgesteld/vastgelegd? | D33: x | E33: x
B34: Hoe heb je de bruikbaarheid van je bevindingen vastgesteld/vastgelegd? | D34: x | E34: x
A36: Beroepstaken | B36: Welke methoden/technieken heb je gebruikt bij het zoeken, verzamelen en beoordelen van informatie? | C36: x | D36: x | E36: x
B37: Welke methoden en technieken passen bij uitstek bij jouw opdracht? | C37: x | D37: x | E37: x
B38: Hoe heb je verzamelde informatie gebruikt om de huidige situatie/probleemdomein te definiëren? | C38: x
B39: Hoe heb je verzamelde informatie gebruikt om de requirements voor betreffende de gewenste situatie vast te stellen? | C39: x | D39: x
B40: Hoe zijn de resultaten van de informatievergaring intersubjectief gemaakt? | D40: x | E40: x
B41: Hoe is tot een prioritering van de opgestelde requirements gekomen? | C41: x | D41: x
B42: Hoe is op basis van de geprioriteerde requirements tot welke oplossing(en) gekomen? | D42: x | E42: x
B43: Hoe is de gap (en de wijze waarop deze overbrugd wordt) tussen de huidige- en de gewenste situatie inzichtelijk gemaakt? | D43: x | E43: x
...

Sheet Beroepstaken
A1: Eindkwalificatie | B1: Code | C1: Beroepstaken | E1: Algemene omschrijving | F1: Voorbeeldskills | G1: Code
A2: A | B2: =$A$2&"-"&C2 -> A-1 | C2: 1 | D2: Analyseren probleemdomein & opstellen probleemstelling | E2: De student brengt helder in kaart waar, wanneer, voor wie en waarom welke problemen zich voordoen, wat de uitgangssituatie is, welke risico's er mogelijk zijn en welke (f)actoren daarbij een rol spelen. | F2: Het uitvoeren van een bedrijfs- of procesanalyse | G2: =$A$2&"-"&C2 -> A-1
F3: Het opstellen van een aanleiding, vraagstelling en doelstelling bij een onderzoek
A4: Analyseren | F4: Het in kaart brengen van de huidige software architectuur
F5: Het uitvoeren van een intake bij een opdrachtgever
A6: Het analyseren van problemen, processen, producten en informatiestromen in onderlinge samenhang en context | F6: Het uitvoeren van een stakeholder- en/of cultuuranalyse
B7: =$A$2&"-"&C7 -> A-2 | C7: 2 | D7: Informatie vergaren, analyseren & verwerken | E7: De student kan methodisch informatie en/of data verzamelen waarbij gemotiveerde keuzes worden gemaakt op basis van relevantie en betrouwbaarheid. De informatie wordt vervolgens geanalyseerd en verwerkt tot (onderdeel van) een eindproduct in de vorm van een literatuurreview, requirementsoverzicht of data-analyse. | F7: Het uitvoeren van brononderzoek | G7: =$A$2&"-"&C7 -> A-2
F8: Het uitvoeren van een statistische analyse
F9: Het houden van gebruikers- / stakeholdersinterviews
F10: Het voorbereiden en uitvoeren van observaties
F11: Het 'cleanen van de data' om tot een bruikbare, consistente dataset te komen.
B12: =$A$2&"-"&C12 -> A-3 | C12: 3 | D12: Informatie beoordelen, waarderen & prioriteren | E12: De student kan de uitkomsten van een informatie analyse beoordelen in het kader van een probleemstelling. Hierbij wordt de betekenis van deze uitkomsten voor een organisatie of stakeholders in kaart gebracht en worden beslissingen genomen ten aanzien van de noodzaak en prioritering | F12: Het prioriteren van requirements | G12: =$A$2&"-"&C12 -> A-3
F13: Het selecteren van te mitigeren risico's
F14: Het trekken van conclusies op basis van onderzoeksuitkomsten
F15: het bediscussiëren van onderzoeksuitkomsten
F16: Het interpreteren van statistieken
B17: =$A$2&"-"&C17 -> A-4 | C17: 4 | D17: Uitvoeren van een onderzoek | E17: De student geeft vorm aan een compleet onderzoekstraject om een informatievraagstuk te beantwoorden. Hierbij worden valide keuzes gemaakt in vraagstelling, onderzoeksmethodiek, participanten en analyse en wordt een onderzoeksverslag, paper of artikel opgesteld. | F17: Het schrijven van een wetenschappelijk artikel | G17: =$A$2&"-"&C17 -> A-4
F18: Het selecteren van een onderzoeksmethodiek
F19: Het definiëren van onderzoeksbegrippen
F20: Het ontwerpen van een experiment
F21: Het ontwikkelen van een meetinstrument
A22: B | B22: =$A$22&"-"&C22 -> B-1 | C22: 1 | D22: Gemotiveerd selecteren van ICT gerelateerde oplossingen | E22: De student kan op methodische wijze komen tot een overzicht van mogelijke oplossingen voor een ICT gerelateerd vraagstuk, en op basis van (een bestaande domein-)analyse komen tot een gemotiveerde selectie van oplossing(en) die de voorkeur genieten. | F22: Het verkennen van nieuwe technologieën en trends | G22: =$A$22&"-"&C22 -> B-1
F23: Het opstellen van criteria voor pakketselectie
A24: Adviseren | F24: Het opstellen van criteria voor componentselectie
F25: Het bepalen van vervolgstappen
A26: Het verantwoord vaststellen van en adviseren over ICT oplossingen en de consequenties voor gebruikers en hun omgeving | F26: Het motiveren van geselecteerde oplossingen
B27: =$A$22&"-"&C27 -> B-2 | C27: 2 | D27: Adviseren over inrichting van ICT gerelateerde oplossingen & processen | E27: De student geeft vorm aan een adviestraject waarin belanghebbenden goed worden betrokken, met als resultaat een passend advies dat op overtuigende wijze is uitgewerkt, goed wordt onderbouwd en op een heldere en aantrekkelijke manier wordt gepresenteerd. | F27: Het opstellen van een adviesrapport | G27: =$A$22&"-"&C27 -> B-2
F28: Het hebben van inzicht in adviesrollen en fasen van een adviesproces
F29: Het geven van een presentatie aan het management
F30: Het opstellen van een implementatieplan
F31: Het opstellen van een benefit logic of business case
A32: C | B32: =$A$32&"-"&C32 -> C-1 | C32: 1 | D32: Ontwerpen software | E32: De student maakt op basis van de analyses en best practices gemotiveerde keuzes voor de opbouw van een software project. Zowel op micro (binnen modules), meso (tussen modules) als macro (module selectie) niveau. | F32: Het ontwerpen van een software architectuur | G32: =$A$32&"-"&C32 -> C-1
F33: Het ontwerpen van een Object Oriented programmeermodel
A34: Ontwerpen | F34: Het hanteren van Design Patterns
F35: Het kiezen tussen verschillende programmeerparadigma's
A36: Het ontwerpen van een ICT gerelateerde oplossing | F36: Het uitwerken van een klassendiagram
B37: =$A$32&"-"&C37 -> C-2 | C37: 2 | D37: Ontwerpen datamodel & database | E37: De student maakt op basis van de analyses en best practices gemotiveerde keuzes voor de opbouw van een datamodel of database. Hierbij wordt aandacht besteed aan de structurering van gegevens, normalisering, performance en concurrency. | F37: Het opstellen van een gegevensmodel voor een database | G37: =$A$32&"-"&C37 -> C-2
F38: Het selecteren van een database paradigma
F39: Het normaliseren van een gegevensmodel
F40: Het selecteren van een kansrijk model t.b.v. 'predictive analysis'
...

Sheet Docentvragen per BT
A1: Hieronder staan voorbeeldvragen die een examinator zou kunnen stellen om een beroepstaak uit te vragen. De voorbeeldvragen betreffen alleen de verplichte beroepstaken.
A3: Vragen A-1: Analyseren probleemdomein & opstellen probleemstelling
A4: Wat heb je gedaan om zicht te krijgen op het probleemgebied?
A5: Hoe heb je de stakeholders in kaart gebracht? Waarom deze stakeholders?
A6: Hoe ben je tot je aanpak gekomen? Op basis waarvan heb je voor deze methoden en technieken gekozen?
A7: Kan je iets vertellen over eventuele wijzigingen in jouw project ten opzichte van de opdracht die je in het voortraject geformuleerd hebt?
A8: In hoeverre kan je de beroepstaken demonstreren met het uitvoeren van de opdracht?
A9: In hoeverre hebben nieuwe inzichten geleid tot een andere aanpak/planning?
A10: Welke stakeholders heb je nodig om de kwaliteit van je beroepsproducten aan te tonen?
A11: Hoe heb je verzamelde informatie gebruikt om de huidige situatie/probleemdomein te definiëren?
A12: Hoe heb je verzamelde informatie gebruikt om de requirements voor je product vast te stellen?
A13: Wat was je doelstelling? In hoeverre heb je je doelstelling bereikt? Hoe heb je dat aangetoond?
... A52: Wat heb je afgeleerd tijdens je afstudeertraject?

Sheet Niveaubepaling
A1: De opleiding sluit voor niveaubepaling aan bij het inschalingsmodel en de beheersings- facetten zoals beschreven in de HBO-i domeinbeschrijving. Hieronder staat deze toegelicht.
A2: Het model laat de relatie zien tussen de beheersingsfacetten (zelfstandigheid en complexiteit van de context en de inhoud). Hieraan wordt invulling gegeven door aan elke combinatie normen te koppelen die leidend zijn in de beoordeling van het betreffende gedrag en de betreffende situatie. In de kolommen van de tabel kun je zien wat er van je verwacht wordt op het gebied van zelfstandigheid, gedrag en complexiteit van je opdracht.

Sheet Beroepstaken per AP
D1: Niveau | E1: 3 | F1: 3 | G1: 3 | H1: 3 | I1: 3 | J1: 3 | K1: 3
D2: Semester | E2: s7 | F2: s7 | G2: s7 | H2: s7 | I2: s7 | J2: s7 | K2: s7
A3: Domein | B3: Eindkwalificatie | C3: Code | D3: Beroepstaak | E3: DGA | F3: IoT | G3: CST | H3: GDS | I3: ISG | J3: INIT** | K3: ICD
A4: A Analyseren | B4: Het analyseren van problemen, processen, producten en informatiestromen in onderlinge samenhang en context | C4: A-1 | D4: Analyseren probleemdomein & opstellen probleemstelling* | E4: x | F4: x | G4: x | H4: x | I4: x | J4: x | K4: x
C5: A-2 | D5: Informatie vergaren, analyseren & verwerken | E5: x | F5: x | G5: x | H5: x | J5: x | K5: x
C6: A-3 | D6: Informatie beoordelen, waarderen & prioriteren | F6: x | I6: x | J6: x | K6: x
C7: A-4 | D7: Uitvoeren van een onderzoek
A8: B Adviseren | B8: Het verantwoord vaststellen van en adviseren over ICT oplossingen en de consequenties voor gebruikers en hun omgeving | C8: B-1 | D8: Gemotiveerd selecteren van ICT gerelateerde oplossingen | F8: x | G8: x | H8: x**
C9: B-2 | D9: Adviseren over inrichting van ICT gerelateerde oplossingen & processen | E9: x | F9: x | G9: x | I9: x | J9: x
A10: C Ontwerpen | B10: Het ontwerpen van een ICT gerelateerde oplossing | C10: C-1 | D10: Ontwerpen software | F10: x | G10: x | H10: x** | K10: x
C11: C-2 | D11: Ontwerpen datamodel & database | E11: x
C12: C-3 | D12: Ontwerpen informatiestructuur
C13: C-4 | D13: Ontwerpen Technische Infrastructuur | F13: x | G13: x
C14: C-5 | D14: Ontwerpen Embedded & Realtime systemen | F14: x | G14: x | H14: x**
C15: C-6 | D15: Ontwerpen van Human Computer Interaction | F15: x | H15: x**
C16: C-7 | D16: Ontwerpen beleid, bedrijfsprocessen & procedures | E16: x | I16: x
C17: C-8 | D17: Ontwerpen stelsel van securitymaatregelen | F17: x | G17: x | I17: x | K17: x
C18: C-9 | D18: Ontwerpen game, computermodel, & simulatie | H18: x
A19: D Realiseren | B19: Het bouwen en/of implementeren van een ICT gerelateerd ontwerp | C19: D-1 | D19: Realiseren van software | F19: x | H19: x* | K19: x
C20: D-2 | D20: Testen & Evalueren | F20: x | G20: x | H20: x* | I20: x | K20: x
C21: D-3 | D21: Realiseren & gebruiken database | E21: x | F21: x
C22: D-4 | D22: Configureren | G22: x | K22: x
C23: D-5 | D23: Implementeren van beleid & advies | I23: x
A24: E Beheren | B24: Het zorgdragen voor een proces van ontwikkeling en duurzaam gebruik van een ICT gerelateerd systeem | C24: E-1 | D24: Beheren van applicaties & technische infrastructuur | F24: x | G24: x | H24: x | K24: x
C25: E-2 | D25: Beheren van data
C26: E-3 | D26: Beheren van risico's | I26: x
A27: F Managen | B27: Het aan informatievoorziening gerelateerd managen van processen en personen | C27: F-1 | D27: Beheersbaar laten verlopen van ontwikkelprocessen | G27: x | H27: x** | K27: x
C28: F-2 | D28: Managen van kennis(processen)
C29: F-3 | D29: Projecten managen | G29: x | H29: x** | I29: x | J29: x
C30: F-4 | D30: Veranderkundig interveniëren | E30: x | I30: x
A31: G Professional skills & attitude | B31: Het inzetten van professionele vaardigheden en het aannemen van een professionele houding binnen een ICT (ontwikkelings)context | C31: G-a | D31: Effectief (Internationaal) Communiceren* | E31: x | F31: x | G31: x | H31: x | I31: x | J31: x | K31: x
C32: G-b | D32: (Internationaal) Samenwerken | F32: x | G32: x | H32: x | I32: x | J32: x | K32: x
C33: G-c | D33: Kritisch, onderzoekend & methodisch werken* | E33: x | F33: x | G33: x | H33: x | I33: x | J33: x | K33: x
C34: G-d | D34: Integer Handelen | E34: x | F34: x | G34: x | I34: x
C35: G-e | D35: Innovatief & creatief werken | F35: x | G35: x | H35: x | I35: x | J35: x
C36: G-f | D36: Leren leren: voorbereiden op volgende studiefase & beroep* | I36: x | J36: x
C37: G-g | D37: Ondernemend handelen
D39: *set beroepstaken verplicht voor iedere afstudeerder
D40: **De aangekruiste beroepstaken zijn onderdeel van de vaste set Innovatieskills. Aanvullend werkt de student aan beroepstaken die inhoudelijk gerelateerd zijn aan de challenge. -->nog opnemen

Sheet Admin
C4: -- Selecteer beroepstaak -- | E4: -- Keuze -- | G4: -- Keuze -- | I4: -- Keuze -- | O4: -- ondertekening --
C5: A-2 Informatie vergaren, analyseren & verwerken | D5: De student kan methodisch informatie en/of data verzamelen waarbij gemotiveerde keuzes worden gemaakt op basis van relevantie en betrouwbaarheid. De informatie wordt vervolgens geanalyseerd en verwerkt tot (onderdeel van) een eindproduct in de vorm van een literatuurreview, requirementsoverzicht of data-analyse. | E5: Goed | G5: BM | I5: BDM | O5: Akkoord
C6: A-3 Informatie beoordelen, waarderen & prioriteren | D6: De student kan de uitkomsten van een informatie analyse beoordelen in het kader van een probleemstelling. Hierbij wordt de betekenis van deze uitkomsten voor een organisatie of stakeholders in kaart gebracht en worden beslissingen genomen ten aanzien van de noodzaak en prioritering | E6: Voldoende | G6: C&A | I6: ISM | O6: Niet akkoord
C7: A-4 Uitvoeren van een onderzoek | D7: De student geeft vorm aan een compleet onderzoekstraject om een informatievraagstuk te beantwoorden. Hierbij worden valide keuzes gemaakt in vraagstelling, onderzoeksmethodiek, participanten en analyse en wordt een onderzoeksverslag, paper of artikel opgesteld. | E7: Nog niet voldoende | G7: CST | I7: NSE | O7: Onder protest akkoord (toelichting in Proces verbaal)
C8: B-1 Gemotiveerd selecteren van ICT gerelateerde oplossingen | D8: De student kan op methodische wijze komen tot een overzicht van mogelijke oplossingen voor een ICT gerelateerd vraagstuk, en op basis van (een bestaande domein-)analyse komen tot een gemotiveerde selectie van oplossing(en) die de voorkeur genieten. | E8: Onvoldoende | G8: DGA | I8: SE
C9: B-2 Adviseren over inrichting van ICT gerelateerde oplossingen & processen | D9: De student geeft vorm aan een adviestraject waarin belanghebbenden goed worden betrokken, met als resultaat een passend advies dat op overtuigende wijze is uitgewerkt, goed wordt onderbouwd en op een heldere en aantrekkelijke manier wordt gepresenteerd. | E9: NVD | G9: GDS | I9: ID
C10: C-1 Ontwerpen software | D10: De student maakt op basis van analyses en best practices gemotiveerde keuzes voor de opbouw van een software project. Zowel op micro (binnen modules), meso (tussen modules) als macro (module selectie) niveau. | E10: Niet van toepassing (in deze fase) | G10: ICD
C11: C-2 Ontwerpen datamodel & database | D11: De student maakt op basis van analyses en best practices gemotiveerde keuzes voor de opbouw van een datamodel of database. Hierbij wordt aandacht besteed aan de structurering van gegevens, normalisering, performance en concurrency. | G11: ID
C12: C-3 Ontwerpen informatiestructuur | D12: De student ontwerpt een structuur op basis waarvan informatie kan worden georganiseerd, gestructureerd en ontsloten, met name op inhoudelijke aspecten. Deze structuur kan de vorm hebben van een informatietaal of een voorstel voor andere vormen van inhoudelijke toegankelijkheid. | G12: IoT
C13: C-4 Ontwerpen Technische Infrastructuur | D13: De student ontwerpt een computernetwerk, dat voldoet aan vooraf gegeven specificaties. Ontwerpkeuzes worden gemotiveerd. Voordat het ontwerp op details wordt uitgewerkt wordt een keuze gemaakt voor een passende n etwe rk/computing-archite ctu u r. | G13: ISG
C14: C-5 Ontwerpen Embedded & Realtime systemen | D14: De student maakt op basis van analyses en best practices gemotiveerde keuzes voor een systeem dat bestaat uit dedicated software die directe interactie heeft met hardware. De uitkomst is een model van de structuur, de functie en het dynamisch gedrag van het systeem. De keuze van hardwarecomponenten en het realiseren van tiidgaranties zijn vaak onderdeel van het ontwerpproces | G14: ISM
C15: C-6 Ontwerpen van Human Computer Interaction | D15: De student ontwerpt prototypes en interfaces om de interactie tussen een interactief computer- of informatiesysteem en gebruikers vorm te geven. Hierbij worden gebruikersgeoriënteerde methodieken ingezet. | G15: SE
C16: C-7 Ontwerpen beleid, bedrijfsprocessen & procedures | D16: De student ontwerpt en formuleert, op basis van een analyse, beleid en procedures ten behoeve van efficiëntie- en effectiviteitsverbetering, waarbij het gebruik van ICT centraal staat en waarbij rekening gehouden wordt met werkbare en haalbare beleidsinstrumenten. | G16: SE dt
C17: C-8 Ontwerpen stelsel van securitymaatregelen | D17: De student ontwerpt een stelsel van samenhangende maatregelen (preventief, detectief, correctief en / of reactief) op basis van organisatiespecifieke risico's en een daaraan gekoppelde risicostrategie. Hierbij wordt gefocust op zowel het beleidsmatige, menselijke als technische aspect.
C18: C-9 Ontwerpen game, computermodel, & simulatie | D18: De student ontwerpt een computerrepresentatie van een stuk (fictieve) werkelijkheid met als doel vermaak, hypothesevorming of prototyping. Hierbij wordt nadrukkelijk aandacht besteed aan de fidelity van weergave, interactie, scenario's en beleving.
C19: D-1 Realiseren van software | D19: De student ontwikkelt een onderbouwd softwareproduct op basis van een ontwerp. Hierbij wordt gebruik gemaakt van programmeer-, opmaak- en scripttalen. Er kan gebruik gemaakt worden van bestaande libraries en frameworks of begonnen worden 'from scratch'.
C20: D-2 Testen & Evalueren | D20: De student toetst of een ontwikkeld ICT product of beleid voldoet aan de opgestelde (niet-)functionele requirements. Hierbij wordt planmatig en volgens best practices gewerkt en waar mogelijk wordt het proces geautomatiseerd. Er wordt aandacht besteed aan het formaliseren van testcases en evaluatiecriteria
C21: D-3 Realiseren & gebruiken database | D21: De student implementeert op basis van een ontwerp een database inclusief de software om de gewenste constraints te realiseren en kan de database effectief en efficiënt bevragen m.b.v. een vraagtaal. De student kan de gerealiseerde database tunen voor optimaal gebruik.
C22: D-4 Configureren | D22: De student stelt op basis van een gegeven ontwerp hardware en softwarecomponenten in om een beoogd IT-systeem te realiseren of optimaliseren.
C23: D-5 Implementeren van beleid & advies | D23: De student draagt er zorg voor dat ontworpen processen, procedures en maatregelen in de organisatie geïmplementeerd worden, ingebed in de bestaande processen en organisatiecultuur. Hierbij gaat de student organisatiesensitief te werk bij het opbouwen van draagvlak
C24: E-1 Beheren van applicaties & technische infrastructuur | D24: De student beheert opgeleverde techniek ten aanzien van veranderende omgevingsfactoren. Dat beheer verloopt volgens een onderbouwd proces dat waar mogelijk gebaseerd is op een standaard of best practice. Het (verloop van het) beheerproces wordt gedocumenteerd. Waar mogelijk speelt toekomstig beheer al een rol tijdens het initiële ontwikkeltraject
C25: E-2 Beheren van data | D25: De student draagt er zorg voor dat de betrouwbaarheid, correctheid, compleetheid en actualiteit van bestaande en nieuwe data geborgd blijft ten aanzien van veranderende omgevingsfactoren
C26: E-3 Beheren van risico's | D26: De student draagt er zorg voor dat organisatierisico's ten aanzien van informatiebeveiliging procesmatig worden beheerd ten aanzien van veranderende omgevingsfactoren
C27: F-1 Beheersbaar laten verlopen van ontwikkelprocessen | D27: De student richt een ontwikkelproces dusdanig in dat voldaan wordt aan tijds-, budget-, kwaliteits- en andere constraints. Waar toepasselijk wordt een gestandaardiseerde aanpak gevolgd en wordt het proces volgens geldende normen gedocumenteerd.
C28: F-2 Managen van kennis(processen) | D28: De student kan kennisgebieden van een organisatie in kaart brengen, becommentariëren en tot stand laten komen door het faciliteren en stimuleren van kennisontwikkeling.
... C39: G-f Leren leren: voorbereiden op volgende studiefase & beroep | D39: De student is in staat het eigen leerproces vorm te geven waarbij voorbereid wordt op life-long-learning.

Sheet Resultaat
A1: -- keuze -- | B1: - | D1: V1 | E1: =VLOOKUP('Fase 1-3'!I10,$A$1:$B$6,2,0) -> - | G1: V ok | H1: =IF(COUNTIF(E1:E4,"<2")=0,"ja","nee") -> ja | I1: =COUNTIF(E1:E4,"<2") -> 0
A2: goed | B2: 3 | D2: V2 | E2: =VLOOKUP('Fase 1-3'!I12,$A$1:$B$6,2,0) -> - | G2: S ok | H2: =IF(COUNTIF(E5:E8,"<2")>1,"nee","ja") -> ja | I2: =COUNTIF(E5:E8,"<2") -> 0
A3: voldoende | B3: 2 | D3: V3 | E3: =VLOOKUP('Fase 1-3'!I14,$A$1:$B$6,2,0) -> - | G3: nvd ok | H3: =IF(COUNTIF(E1:E8,"-")=8,"ja",(IF(AVERAGE(E1:E8)=0,"nee","ja"))) -> ja
A4: onvoldoende | B4: 1 | D4: V4 | E4: =VLOOKUP('Fase 1-3'!I16,$A$1:$B$6,2,0) -> - | G4: onvoldoende | H4: =IF(OR(H1="nee",H2="nee",H3="nee"),"ja","nee") -> nee
A5: niet van toepassing | B5: - | D5: S1 | E5: =VLOOKUP('Fase 1-3'!I18,$A$1:$B$6,2,0) -> -
A6: nvd | B6: 0 | D6: S2 | E6: =VLOOKUP('Fase 1-3'!I20,$A$1:$B$6,2,0) -> -
D7: S3 | E7: =VLOOKUP('Fase 1-3'!I22,$A$1:$B$6,2,0) -> -
A8: Gemiddelde > | B8: Indicatie | D8: S4 | E8: =VLOOKUP('Fase 1-3'!I24,$A$1:$B$6,2,0) -> -
A9: 2.75 | B9: 9 <> 10 | D9: gem | E9: =IF(COUNTIF(E1:E8,"-")=8,"",AVERAGE(E1:E8))
A10: 2.5 | B10: 8 <> 9
A11: 2.25 | B11: 7 <> 8
A12: 2 | B12: 6 <> 7
A13: 1.75 | B13: 5,5 <> 6
A14: onvoldoende = ja | B14: < 5,5
A16: Resultaat | B16: {=IF(H4="ja",$B$14,(IF(E9="","",_1__xlfn.IFS(E9>=$A$9,$B$9,E9>=$A$10,$B$10,E9>=$A$11,$B$11,E9>=$A$12,$B$12,E9>=$A$13,$B$13))))}

Sheet her
A1: -- keuze -- | B1: - | D1: V1 | E1: =VLOOKUP(Herkansing!E9,$A$1:$B$6,2,0) -> - | G1: V ok | H1: =IF(COUNTIF(E1:E4,"<2")=0,"ja","nee") -> ja | I1: =COUNTIF(E1:E4,"<2") -> 0
A2: goed | B2: 3 | D2: V2 | E2: =VLOOKUP(Herkansing!E11,$A$1:$B$6,2,0) -> - | G2: S ok | H2: =IF(COUNTIF(E5:E8,"<2")>1,"nee","ja") -> ja | I2: =COUNTIF(E5:E8,"<2") -> 0
A3: voldoende | B3: 2 | D3: V3 | E3: =VLOOKUP(Herkansing!E13,$A$1:$B$6,2,0) -> - | G3: nvd ok | H3: =IF(COUNTIF(E1:E8,"-")=8,"ja",(IF(AVERAGE(E1:E8)=0,"nee","ja"))) -> ja
A4: onvoldoende | B4: 1 | D4: V4 | E4: =VLOOKUP(Herkansing!E15,$A$1:$B$6,2,0) -> - | G4: onvoldoende | H4: =IF(OR(H1="nee",H2="nee",H3="nee"),"ja","nee") -> nee
A5: niet van toepassing | B5: - | D5: S1 | E5: =VLOOKUP(Herkansing!E17,$A$1:$B$6,2,0) -> -
A6: nvd | B6: 0 | D6: S2 | E6: =VLOOKUP(Herkansing!E19,$A$1:$B$6,2,0) -> -
D7: S3 | E7: =VLOOKUP(Herkansing!E21,$A$1:$B$6,2,0) -> -
A8: Gemiddelde > | B8: Indicatie | D8: S4 | E8: =VLOOKUP(Herkansing!E23,$A$1:$B$6,2,0) -> -
A9: 2.75 | B9: 9 <> 10 | D9: gem | E9: =IF(COUNTIF(E1:E8,"-")=8,"",AVERAGE(E1:E8))
A10: 2.5 | B10: 8 <> 9
A11: 2.25 | B11: 7 <> 8
A12: 2 | B12: 6 <> 7
A13: 1.75 | B13: 5,5 <> 6
A14: onvoldoende = ja | B14: < 5,5
A16: Resultaat | B16: {=IF(H4="ja",$B$14,(IF(E9="","",_1__xlfn.IFS(E9>=$A$9,$B$9,E9>=$A$10,$B$10,E9>=$A$11,$B$11,E9>=$A$12,$B$12,E9>=$A$13,$B$13))))}
